Workbook
Name Accessories_Extras: 'Outdoor Blinds'!$D$1348
Name Accessories_Extras: #REF!
Name Fixed_Channel_Screens_Category_Five: 'Outdoor Blinds'!$C$1160
Name Fixed_Channel_Screens_Category_Five: #REF!
Name Fixed_Channel_Screens_Category_Four: 'Outdoor Blinds'!$C$1138
Name Fixed_Channel_Screens_Category_Four: #REF!
Name Fixed_Channel_Screens_Category_One: 'Outdoor Blinds'!$C$1063
Name Fixed_Channel_Screens_Category_One: #REF!
Name Fixed_Channel_Screens_Category_Three: 'Outdoor Blinds'!$C$1113
Name Fixed_Channel_Screens_Category_Three: #REF!
Name Fixed_Channel_Screens_Category_Two: 'Outdoor Blinds'!$C$1091
Name Fixed_Channel_Screens_Category_Two: #REF!
Name Motorisation: 'Outdoor Blinds'!$H$1380
Name Motorisation: #REF!
Name Ombra_ToC: 'Outdoor Blinds'!$B$6
Name Ombra_ToC: #REF!
Name Reskin_for_Awnings_Category_Five: 'Outdoor Blinds'!$C$1303
Name Reskin_for_Awnings_Category_Five: #REF!
Name Reskin_for_Awnings_Category_Four: 'Outdoor Blinds'!$C$1276
Name Reskin_for_Awnings_Category_Four: #REF!
Name Reskin_for_Awnings_Category_One: 'Outdoor Blinds'!$C$1186
Name Reskin_for_Awnings_Category_One: #REF!
Name Reskin_for_Awnings_Category_Three: 'Outdoor Blinds'!$C$1246
Name Reskin_for_Awnings_Category_Three: #REF!
Name Reskin_for_Awnings_Category_Two: 'Outdoor Blinds'!$C$1219
Name Reskin_for_Awnings_Category_Two: #REF!
Name Sail_Track_Screens_Category_Five: 'Outdoor Blinds'!$C$1048
Name Sail_Track_Screens_Category_Five: #REF!
Name Sail_Track_Screens_Category_Four: 'Outdoor Blinds'!$C$1016
Name Sail_Track_Screens_Category_Four: #REF!
Name Sail_Track_Screens_Category_One: 'Outdoor Blinds'!$C$944
Name Sail_Track_Screens_Category_One: #REF!
Name Sail_Track_Screens_Category_Three: 'Outdoor Blinds'!$C$991
Name Sail_Track_Screens_Category_Three: #REF!
Name Sail_Track_Screens_Category_Two: 'Outdoor Blinds'!$C$969
Name Sail_Track_Screens_Category_Two: #REF!
Name Straight_Drop_Awnings_Category_Five: 'Outdoor Blinds'!$C$547
Name Straight_Drop_Awnings_Category_Five: #REF!
Name Straight_Drop_Awnings_Category_Four: 'Outdoor Blinds'!$C$516
Name Straight_Drop_Awnings_Category_Four: #REF!
Name Straight_Drop_Awnings_Category_One: 'Outdoor Blinds'!$C$414
Name Straight_Drop_Awnings_Category_One: #REF!
Name Straight_Drop_Awnings_Category_Three: 'Outdoor Blinds'!$C$482
Name Straight_Drop_Awnings_Category_Three: #REF!
Name Straight_Drop_Awnings_Category_Two: 'Outdoor Blinds'!$C$451
Name Straight_Drop_Awnings_Category_Two: #REF!
Name Wire_Guide_Awnings_Category_Five: 'Outdoor Blinds'!$C$381
Name Wire_Guide_Awnings_Category_Five: #REF!
Name Wire_Guide_Awnings_Category_Four: 'Outdoor Blinds'!$C$350
Name Wire_Guide_Awnings_Category_Four: #REF!
Name Wire_Guide_Awnings_Category_One: 'Outdoor Blinds'!$C$248
Name Wire_Guide_Awnings_Category_One: #REF!
Name Wire_Guide_Awnings_Category_Three: 'Outdoor Blinds'!$C$316
Name Wire_Guide_Awnings_Category_Three: #REF!
Name Wire_Guide_Awnings_Category_Two: 'Outdoor Blinds'!$C$285
Name Wire_Guide_Awnings_Category_Two: #REF!
Name Wire_Guide_Extreme_Awnings_Category_Five: 'Outdoor Blinds'!$C$908
Name Wire_Guide_Extreme_Awnings_Category_Five: #REF!
Name Wire_Guide_Extreme_Awnings_Category_Four: 'Outdoor Blinds'!$C$874
Name Wire_Guide_Extreme_Awnings_Category_Four: #REF!

Sheet Cover
B21: Product Category Price List
B29: **All downloaded Pricelists can be found on separate sheets in the footer of this document**
B55: Luxe Blinds Shutters Awnings
L58: As of
I59: =TODAY() -> 46113

Sheet Bayview
B2: Plantation Shutters | F2: As of | G2: =Cover!I59 -> 46113
A3: Bayview Collection | E3: Luxe Blinds Shutters Awnings
A5: Basswood
A6: Knoxcote solid paint | F6: 240
A7: Knoxcote stained | F7: 276
A8: Ardenwood
A9: Select paint | F9: 220
A10: ThermoPoly | L10: 10
A11: Knoxcote paint | F11: 240
A12: Veilcote paint | F12: =F13+L10 -> 212
A13: Select paint | F13: 202
A14: Thermotec
A15: Knoxcote paint | F15: 240
A16: Price includes: framing*, hinges and magnets if required
A17: NOTE: Minimum charge 1m² per item
A19: Additional Charges
A20: Custom Colour | F20: $300 /colour
A21: Raked Shutters (uneven sides) | F21: $315 /item
A22: Shaped Shutter | F22: $420 /item
A23: French Door Cut Out | F23: $275 /cut out
A24: Bay & Corner Window | F24: $18 /m²
A25: Internal Tilt | F25: $15 /m²
A26: Flat Stile – 90mm Flat Stile | F26: $18 /m²
A27: Stainless Steel Hinges | F27: $18 /m²
A28: Fly Screen Build Out | F28: $18 /m²
A29: Frame Build Outs - Small (<20mm) | F29: $18 /m²
A30: Frame Build Outs - Large (>20mm) | F30: $28 /m²
A31: Frame Cut Out | F31: $18 /cutout
... A38: Extra Blades | F38: $18 /blade
A39: Sliding & Bifold Tracking System
A40: Above prices include: hardware, head bAbove prices include: hardware, head board, side boards, top and bottom track (even if some items are not needed).oard, side boards, top and bottom track (even if some items are not needed).
A41: Single Track Sliding or Bifold | F41: $165 /LM - Min 2/LM
A42: Double Track Sliding | F42: $240 /LM - Min 2/LM
A43: Triple Track Sliding | F43: $240 /LM - Min 2/LM
A44: Sliding & Bifold Tracking System
A45: Joinery Size | D45: Painted | F45: Stained
A46: Joinery - Size <20x20 | D46: $10 /LM | F46: $15 /LM
A47: Joinery - Size <30x30 | D47: $12 /LM | F47: $17 /LM
A48: Joinery - Size <40x40 | D48: $15 /LM | F48: $19 /LM
A49: Joinery - Size <50x50 | D49: $19 /LM | F49: $24 /LM
...

Sheet Bayview S2
B2: Plantation Shutters | F2: As of | G2: =Cover!I59 -> 46113
A3: Bayview II Collection | E3: Luxe Blinds Shutters Awnings
A5: Basswood
A6: Knoxcote - Solid Paint | F6: 247
A7: Knoxcote - Stained | F7: 283
A8: Ardenwood
A9: Knoxcote - Solid Paint | F9: 236
A10: Knoxcote - Brushed Finish | F10: 273
A11: Select paint | F11: 220
A12: ThermoPoly
A13: Knoxcote - Solid Paint | F13: 247
A14: Select paint | F14: 200
A15: Price includes: framing*, hinges and magnets if required
A16: NOTE: Minimum charge 1m² per item
A17: Additional Charges
A18: Custom Colour | F18: 300
A19: Shaped Shutter (all shapes) - Min 1 sqm | F19: 130
A20: French Door Cut Out | F20: 275
A21: Bay & Corner Window | F21: 21
A22: Internal Tilt | F22: 24
A23: Flat Stile – 90mm Flat Stile | F23: 21
A24: 15mm Thick Blades (Basswood) | F24: 28
A25: Stainless Steel Hinges/Hidden Hinge | F25: 18
A26: Fly Screen Build Out | F26: 18
A27: Frame Build Outs - Small (<20mm) | F27: 18
A28: Frame Build Outs - Large (>20mm) | F28: 26
A29: Frame Cut Out | F29: 18
... A36: Solid Panels | F36: 15
A37: Sliding & Bifold Tracking System
A38: Above prices include: hardware, head bAbove prices include: hardware, head board, side boards, top and bottom track (even if some items are not needed).oard, side boards, top and bottom track (even if some items are not needed).
A39: Single Track Sliding or Bifold | F39: $165 /LM - Min 2/LM
A40: Double Track Sliding | F40: $240 /LM - Min 2/LM
A41: Triple Track Sliding | F41: $300 /LM - Min 2/LM
A42: Sliding & Bifold Tracking System
A43: Joinery Size | D43: Painted | F43: Stained
A44: Joinery - Size <20x20 | D44: $10 /LM | F44: $15 /LM
A45: Joinery - Size <30x30 | D45: $13 /LM | F45: $17 /LM
A46: Joinery - Size <40x40 | D46: $15 /LM | F46: $19 /LM
A47: Joinery - Size <50x50 | D47: $19 /LM | F47: $24 /LM
A48: Joinery - Size <60x60 | D48: $21 /LM | F48: $26 /LM
...

Sheet Forte
B2: Plantation Shutters | F2: As of | G2: =Cover!I59 -> 46113
A3: Forte Collection | E3: Luxe Blinds Shutters Awnings
A5: ThermoPoly
A6: Veilcote paint | F6: =J6+K6 -> 194 | J6: 184 | K6: 10
A7: Select paint | F7: 184
A8: Price includes: framing*, hinges and magnets if required
A9: NOTE: Minimum charge 1m² per item
A10: Additional Charges
A11: Raked Shutters (uneven sides) | F11: $315 /item
A12: Shaped Shutter | F12: $420 /item
A13: French Door Cut Out | F13: $275 /cut out
A14: Bay & Corner Window | F14: $18 /m²
A15: Internal Tilt | F15: $15 /m²
A16: Stainless Steel Hinges | F16: $18 /m²
A17: Fly Screen Build Out | F17: $18 /m²
A18: Frame Build Outs - Small (<20mm) | F18: $18 /m²
A19: Frame Build Outs - Large (>20mm) | F19: $28 /m²
A20: Frame Cut Out | F20: $18 /cutout
A21: Tier on Tier | F21: $28 /m²
A22: Star Key Lock | F22: $45 each
A23: Extra Blades | F23: $18 /blade
A24: Sliding & Bifold Tracking System
A25: Above prices include: hardware, head bAbove prices include: hardware, head board, side boards, top and bottom track (even if some items are not needed).oard, side boards, top and bottom track (even if some items are not needed).
A26: Single Track Sliding or Bifold | F26: $165 /LM - Min 2/LM
A27: Double Track Sliding | F27: $240 /LM - Min 2/LM
A28: Triple Track Sliding | F28: $240 /LM - Min 2/LM
A29: Joinery
A30: Joinery Size | F30: Painted
A31: Joinery - Size <20x20 | F31: $10 /LM
A32: Joinery - Size <30x30 | F32: $12 /LM
A33: Joinery - Size <40x40 | F33: $15 /LM
A34: Joinery - Size <50x50 | F34: $19 /LM
A35: Joinery - Size <60x60 | F35: $21 /LM
A36: Prices do not include any applicable shipping/handling fees.
A38: All prices are subject to 10% GST. Prices subject to change without notice. All prices subject to CW Systems’ General Terms & Conditions.

Sheet Oasis
B2: Plantation Shutters | F2: As of | G2: =Cover!I59 -> 46113
A3: Oasis Collection | E3: Luxe Blinds Shutters Awnings
A5: ThermoPoly (Price includes: framing*, hinges and magnets if required)
A6: Knoxcote paint | F6: $202/m²
A7: NOTE: Minimum charge 1m² per item
A8: Additional Charges
A9: Bay & Corner Window | F9: $12 /m²
A10: Shaped Shutters | F10: $200 /m²
A11: French Door Cut Out | F11: $375 /item
A12: Custom Colour | F12: $75 /Sqm - min 5sqm
A13: Stainless Steel Hinges | F13: $24 /m²
A14: Frame Build out | F14: $18 /m²
A15: Frame Cut Out | F15: $18 /cut out
A16: Tier on Tier | F16: $24 /m²
A17: Large Z-Frame Surcharge - Large Bullnose Z-Frame - Deluxe Z-Frame - Elegant Z-Frame - Deco Z-Frame - Flat Z-Frame | F17: $25 /m²
A18: Face Fit L-Frame Surcharge - 72mm Face Fit L-Frame - Deco Face Fit L-Frame | F18: $15 /m²
A19: Flush Bolt | F19: $12 /each
A20: Extra Blades | F20: $19 /blade
A21: Standard Joinery
A22: Joinery - 17.1 x 17.1mm | F22: $10 /LM
A23: Joinery - 40 x 38mm | F23: $13 /LM
A24: Joinery - 53.8 x 38.1mm | F24: $18 /LM
A25: Custom Joinery
A26: Joinery < 20x20 | F26: $11.5 /LM
A27: Joinery < 30x30 | F27: $13.5 /LM
A28: Joinery < 40x40 | F28: $17 /LM
A29: Joinery < 50x50 | F29: $23 /LM
A30: Joinery < 60x60 | F30: $30 /LM
A31: Tracking
A32: Single Track Bi-Fold/Sliding | F32: $165 /LM - min 2 LM
A33: Double Track Sliding | F33: $240 /LM - min 2 LM
A34: Triple Track Sliding | F34: $300 /LM - min 2 LM
A35: Prices do not include any applicable shipping/handling fees.
A36: All prices are subject to 10% GST. Prices subject to change without notice. All prices subject to CW Systems’ General Terms & Conditions.

Sheet Imported Alum.
B2: Plantation Shutters | F2: As of | G2: =Cover!I59 -> 46113
A3: Vueline Collection | E3: Luxe Blinds Shutters Awnings
A5: ForgeCote Standard panels with 90mm & 115mm Blades
A6: Panels Only | E6: 287 | G6: /m² *
A7: Fixed in U-Channel (inc. U-channels, H-Section, side channels, angles) | E7: 308 | G7: /m² *
A8: Hinged in Frame | E8: 330 | G8: /m² *
B9: Surcharge: 63mm Blade | E9: 57 | G9: /m²
B10: Surcharge: 150mm Blade | E10: 67 | G10: /m²
A11: *Minimum 1 m² / Item
A12: Fixed Blade Shutters
A13: ForgeCote Fixed Blades with 50x3mm Flatbar stiles
A14: Standard panels (90mm Blades) | E14: 270 | G14: /m² *
B15: Surcharge: 63mm Blade | E15: 67 | G15: /m²
A16: Fixed Blades with 100x3mm Flatbar stiles
A17: Standard panels (115mm Blades) | E17: =E14+AC17 -> 270 | G17: /m² * | AA17: 67
B18: Surcharge: 150mm Blade | E18: 88 | G18: /m² *
A19: Fixed Blade w/ Box Section Stiles
A20: Standard Panels (90mm Blades) | E20: 316 | G20: /m² *
A21: Standard Panels (115mm Blades) | E21: 386 | G21: /m² *
A22: *Minimum 1 m² / Item
A23: Fixed Blade Sunhoods
A24: Sunhoods with 50mm Support Beams
A25: Sunhood panels (90mm Blades) | E25: 270 | G25: /m² *
A26: 50mm Support Beams (Include Wall Mount) | E26: 42 | G26: /Lm
A27: *Minimum 1 m² / Item
A28: Vertical Louvres
A29: Vertical Louvres w/ Top & Bottom 100x50mm Stiles
A30: Operable Vertical Louvres - 150mm | E30: 588 | G30: /m² *
A31: Fixed Vertical Louvres - 150mm | E31: 537 | G31: /m² *
A32: *Minimum 1 m² / Item
A33: Colour Surcharges
A34: Custom & Woodgrain Colours | E34: $75/sqm - Minimum 5/sqm
A35: Prices do not include any applicable shipping/handling fees.
A36: All prices are subject to 10% GST. Prices subject to change without notice. All prices subject to CW Systems’ General Terms & Conditions.
A38: Locks & Bolts
A39: Flush Bolts | E39: $42 each
A40: Door Handle Lock | E40: $95 each
A41: Dead Lock | E41: $95 each
A42: Blade Lock | E42: $27 each
A43: Mounting Brackets
...

Sheet Local Poly
B2: Plantation Shutters | F2: As of | G2: =Cover!I59 -> 46113
A3: Local Made Poly Shutters | E3: Luxe Blinds Shutters Awnings
A5: Local Made Poly Shutter | E5: 245 | G5: /m²*
D6: *Min 1m² /item
A7: Additional Charges
A8: Bay & Corner Window | F8: $22 /m²
A9: Tier on Tier Surchage | F9: $30 /m²
A10: Frame Buildout | F10: $20 /m²
A11: • All Panels wraped in bubble wrap and have plastic coating on blades and stiles. This is suitable for pick-up or delivery with our in house logistics. If you are outside this area please ask for Extra Packaging.
A12: • Price includes Framing, Hinges & Magnets
A13: Lead Times
A14: • 2-3 Week Lead times
A15: Specifications
A16: Max Panel Width | E16: 800mm
A17: Max Panel Height | E17: 2400mm
A18: Mid rail required for panels over height | E18: 1500mm
A19: Clearview max length | E19: 1200mm
A20: Warranty | E20: 20 Years Material / 5 Years Paint
A21: Options
A22: Stiles | D22: 51mm Beaded - Square & D-Mould
A23: Blades | D23: 89mm Blade ( Aluminium Insert )
A24: Shutter Types | D24: Hinged, Fixed or Panel only
A25: Colours
A26: Frames
A29: Prices do not include any applicable shipping/handling fees.
A30: All prices are subject to 10% GST. Prices subject to change without notice. All prices subject to CW Systems’ General Terms & Conditions.

Sheet Outdoor Blinds
D2: Outdoor Blinds | X2: As of | Y2: =Cover!I59 -> 46113
C3: Ombra Collection | W3: Luxe Blinds Shutters Awnings
AE5: Awning Discount | AF5: -35
B6: Table of Contents
C7: Zipscreen System 78 (Standard ) | O7: Page 2
C8: Wire Guide System 78 (Standard) | O8: Page 5
C9: Straight Drop Blind System 78 (Standard) | O9: Page 8
C10: Zipscreen System 110 (Extreme) | O10: Page 11
C11: Wireguide System 110 (Extreme) | O11: Page 14
C12: Sail Track Fixed Screens | O12: Page 17
C13: Channel Fixed Screens | O13: Page 20
C14: Reskin / Skin Only | O14: Page 23
C15: Assessories & Motorisation | O15: Page 26
B18: Fabric Categories
C20: Fabric Category 1
C21: Fabric Range Name | I21: Brand | O21: Fabric Type | U21: Fabric Width
C22: Ombra 6% Fabric | I22: Cotewood | O22: 2 x 2 PVC Mesh | U22: 3200 mm
C23: Skyline 94 | I23: Ricky Richards | O23: 2 x 2 PVC Mesh | U23: 3200 mm
C24: Fabric Category 2
C25: Fabric Range Name | I25: Brand | O25: Fabric Type | U25: Fabric Width
C26: Ombra 1% Fabric | I26: Cotewood | O26: 2 x 2 PVC Mesh | U26: 3200 mm
C27: Skyline 99 | I27: Ricky Richards | O27: 2 x 2 PVC Mesh | U27: 3200 mm
C28: Mode 95 | I28: Outlook - Ricky Richards | O28: 2 x 2 PVC Mesh | U28: 3200 mm
C29: Mode Designs 95 | I29: Outlook - Ricky Richards | O29: 2 x 2 PVC Mesh | U29: 3000 mm
C30: Vistaweave 95 | I30: Vistaweave - Nolans | O30: 2 x 2 PVC Mesh | U30: 3200 mm
C31: Vistaweave Stripe 95 | I31: Vistaweave - Nolans | O31: 2 x 2 PVC Mesh | U31: 3000 mm
C32: Dayscreen 5% | I32: Shaw Fabrics | O32: 2 x 2 PVC Mesh | U32: 3200 mm
C33: Visiontex View | I33: Visiontex - HVG | U33: 3200 mm
C34: Visiontex Plus | I34: Visiontex - HVG | U34: 3200 mm
C35: Fabric Category 3
C36: Fabric Range Name | I36: Brand | O36: Fabric Type | U36: Fabric Width
C37: Mode Textures | I37: Outlook - Ricky Richards | O37: 2 x 2 PVC Mesh | U37: 3200 mm
C38: Dayscreen 1% | I38: Shaw Fabrics
C39: Visiontex Ultra | I39: Visiontex - HVG
C40: Visiontex Extreme | I40: Visiontex - HVG
C41: Fabric Category 4
C42: Fabric Range Name | I42: Brand | O42: Fabric Type | U42: Fabric Width
C43: Mode Privacy 99% | I43: Outlook - Ricky Richards | U43: 3200 mm
C44: Mode Zero | I44: Outlook - Ricky Richards
C45: Vistaweave 99% | I45: Vistaweave - Nolans
...

Sheet Pleated
B2: Insect Screens | G2: As of | H2: =Cover!I59 -> 46113
A3: Element Collection | F3: Luxe Blinds Shutters Awnings
D4: =IFERROR(IF(-X4/100>0,-X4/100,""),"") -> 0.25 | E4: =IF(D4="","","Discount already applied to the prices below") -> Discount already applied to the prices below | X4: -25
A5: Pleated Screen Price List
A6: Standard Single
A7: WIDTH
A8: HEIGHT | C8: 1100 | D8: 1500 | E8: 2000 | F8: 2700 | G8: 3600 | H8: 4500
B9: 800 | C9: 270 | D9: 334.5 | E9: 399.75 | F9: n/a | G9: n/a | H9: n/a
B10: 1000 | C10: 316.5 | D10: 384.75 | E10: 454.5 | F10: n/a | G10: n/a | H10: n/a
B11: 1200 | C11: 327 | D11: 396.75 | E11: 466.5 | F11: 526.5 | G11: n/a | H11: n/a
B12: 1400 | C12: 429.75 | D12: 540 | E12: 651.75 | F12: 753.75 | G12: n/a | H12: n/a
B13: 1600 | C13: 466.5 | D13: 576 | E13: 687 | F13: 789.75 | G13: 990.75 | H13: n/a
B14: 1800 | C14: 483.75 | D14: 594.75 | E14: 706.5 | F14: 809.25 | G14: 1008.75 | H14: n/a
B15: 2000 | C15: 486 | D15: 598.5 | E15: 709.5 | F15: 812.25 | G15: 1011.75 | H15: 1157.25
B16: 2200 | C16: 493.5 | D16: 604.5 | E16: 714.75 | F16: 820.5 | G16: 1019.25 | H16: 1165.5
B17: 2400 | C17: 500.25 | D17: 610.5 | E17: 720 | F17: 828.75 | G17: 1026.75 | H17: 1173
B18: 2600 | C18: 546.75 | D18: 664.5 | E18: 782.25 | F18: 900 | G18: 1120.5 | H18: 1283.25
B19: 2800 | C19: 574.5 | D19: 698.25 | E19: 821.25 | F19: 945 | G19: 1176 | H19: 1347.75
B20: 3000 | C20: 591 | D20: 718.5 | E20: 846 | F20: 974.25 | G20: 1211.25 | H20: 1387.5
A22: Standard Double
A23: WIDTH
A24: HEIGHT | C24: 2200 | D24: 3000 | E24: 4000 | F24: 5400 | G24: 7200 | H24: 9000
B25: 800 | C25: 538.5 | D25: 669 | E25: 799.5 | F25: n/a | G25: n/a | H25: n/a
B26: 1000 | C26: 632.25 | D26: 769.5 | E26: 908.25 | F26: n/a | G26: n/a | H26: n/a
B27: 1200 | C27: 653.25 | D27: 792 | E27: 931.5 | F27: 1051.5 | G27: n/a | H27: n/a
B28: 1400 | C28: 859.5 | D28: 1080 | E28: 1302 | F28: 1506.75 | G28: n/a | H28: n/a
B29: 1600 | C29: 931.5 | D29: 1151.25 | E29: 1374 | F29: 1578.75 | G29: 1980 | H29: n/a
B30: 1800 | C30: 966.75 | D30: 1188.75 | E30: 1412.25 | F30: 1617.75 | G30: 2016.75 | H30: n/a
B31: 2000 | C31: 971.25 | D31: 1196.25 | E31: 1418.25 | F31: 1624.5 | G31: 2022 | H31: 2313.75
B32: 2200 | C32: 985.5 | D32: 1207.5 | E32: 1429.5 | F32: 1641 | G32: 2037.75 | H32: 2329.5
B33: 2400 | C33: 999.75 | D33: 1220.25 | E33: 1439.25 | F33: 1656.75 | G33: 2053.5 | H33: 2346
B34: 2600 | C34: 1092.75 | D34: 1329 | E34: 1563.75 | F34: 1800 | G34: 2239.5 | H34: 2565.75
B35: 2800 | C35: 1147.5 | D35: 1395 | E35: 1642.5 | F35: 1890 | G35: 2351.25 | H35: 2694.75
B36: 3000 | C36: 1181.25 | D36: 1436.25 | E36: 1691.25 | F36: 1947.75 | G36: 2421.75 | H36: 2775
A38: Vertical
A39: WIDTH
A40: HEIGHT | C40: 500 | D40: 1000 | E40: 1500 | F40: 2000 | G40: 2500 | H40: 3000
B41: 500 | C41: 285 | D41: 318 | E41: 359.25 | F41: 383.25 | G41: 410.25 | H41: 475.5
B42: 1000 | C42: 330.75 | D42: 366.75 | E42: 413.25 | F42: 436.5 | G42: 463.5 | H42: 540
B43: 1500 | C43: 377.25 | D43: 415.5 | E43: 465.75 | F43: 489 | G43: 517.5 | H43: 605.25
...

Sheet Lumex Custom
B2: Roofing | E2: CUSTOM ROOF Price List | M2: As of | N2: =Cover!I59 -> 46113
A3: Lumex Collection - SkyStrong 220 | M3: Luxe Blinds Shutters Awnings
J4: =IFERROR(IF(-Q4/100>0,-Q4/100,""),"") -> 0.1 | L4: =IF(J4="","","Discount already applied to the prices below") -> Discount already applied to the prices below | Q4: -10
A5: Prices include: Blades, Gutters, Pivot Rails; Monument & White colours only (see below for surcharge on other colours)
C7: Width (mm)
A8: No. of Blades | B8: Projection | C8: 1500 | D8: 1750 | E8: 2000 | F8: 2250 | G8: 2500 | H8: 2750 | I8: 3000 | J8: 3250 | K8: 3500 | L8: 3750 | M8: 4000 | N8: 4250 | O8: 4500
A9: 7 | B9: 1400 | C9: 1955.7 | D9: 2099.7 | E9: 2263.5 | F9: 2425.5 | G9: 2589.3 | H9: 2733.3 | I9: 2897.1 | J9: 3059.1 | K9: 3222.9 | L9: 3366.9 | M9: 3529.8 | N9: 3692.7 | O9: 3855.6
A10: 8 | B10: 1600 | C10: 2153.7 | D10: 2335.5 | E10: 2516.4 | F10: 2697.3 | G10: 2878.2 | H10: 3059.1 | I10: 3240 | J10: 3420.9 | K10: 3584.7 | L10: 3765.6 | M10: 3945.6 | N10: 4126.5 | O10: 4307.4
A11: 9 | B11: 1800 | C11: 2390.4 | D11: 2570.4 | E11: 2770.2 | F11: 2969.1 | G11: 3167.1 | H11: 3366.9 | I11: 3565.8 | J11: 3765.6 | K11: 3964.5 | L11: 4163.4 | M11: 4363.2 | N11: 4561.2 | O11: 4760.1
A12: 10 | B12: 2000 | C12: 2589.3 | D12: 2806.2 | E12: 3023.1 | F12: 3258 | G12: 3457.8 | H12: 3692.7 | I12: 3910.5 | J12: 4126.5 | K12: 4344.3 | L12: 4561.2 | M12: 4779 | N12: 4995.9 | O12: 5212.8
A13: 11 | B13: 2200 | C13: 2806.2 | D13: 3041.1 | E13: 3294 | F13: 3529.8 | G13: 3765.6 | H13: 4000.5 | I13: 4236.3 | J13: 4471.2 | K13: 4706.1 | L13: 4959.9 | M13: 5194.8 | N13: 5430.6 | O13: 5230.8
A14: 12 | B14: 2400 | C14: 3023.1 | D14: 3276.9 | E14: 3547.8 | F14: 3800.7 | G14: 4054.5 | H14: 4307.4 | I14: 4579.2 | J14: 4833 | K14: 5085.9 | L14: 5339.7 | M14: 5176.8 | N14: 5411.7 | O14: 5647.5
A15: 13 | B15: 2600 | C15: 3240 | D15: 3529.8 | E15: 3800.7 | F15: 4072.5 | G15: 4344.3 | H15: 4633.2 | I15: 4905 | J15: 5194.8 | K15: 5466.6 | L15: 5303.7 | M15: 5557.5 | N15: 5810.4 | O15: 6081.3
A16: 14 | B16: 2800 | C16: 3457.8 | D16: 3765.6 | E16: 4054.5 | F16: 4344.3 | G16: 4652.1 | H16: 4941 | I16: 5249.7 | J16: 5538.6 | K16: 5393.7 | L16: 5665.5 | M16: 5937.3 | N16: 6208.2 | O16: 6498
A17: 15 | B17: 3000 | C17: 3674.7 | D17: 4000.5 | E17: 4307.4 | F17: 4633.2 | G17: 4941 | H17: 5266.8 | I17: 5574.6 | J17: 5447.7 | K17: 5737.5 | L17: 6027.3 | M17: 6317.1 | N17: 6334.2 | O17: 6624.9
A18: 16 | B18: 3200 | C18: 3891.6 | D18: 4217.4 | E18: 4561.2 | F18: 4905 | G18: 5249.7 | H18: 5574.6 | I18: 5918.4 | J18: 5773.5 | K18: 6081.3 | L18: 6407.1 | M18: 6425.1 | N18: 6732.9 | O18: 7022.7
A19: 17 | B19: 3400 | C19: 4109.4 | D19: 4452.3 | E19: 4814.1 | F19: 5176.8 | G19: 5538.6 | H19: 5900.4 | I19: 5773.5 | J19: 6099.3 | K19: 6425.1 | L19: 6769.8 | M19: 6786.9 | N19: 7112.7 | O19: 7420.5
A20: 18 | B20: 3600 | C20: 4326.3 | D20: 4706.1 | E20: 5067.9 | F20: 5447.7 | G20: 5827.5 | H20: 5737.5 | I20: 6081.3 | J20: 6425.1 | K20: 6786.9 | L20: 6823.8 | M20: 7167.6 | N20: 7493.4 | O20: 7837.2
... A42: 40 | B42: 8000 | C42: 8996.4 | D42: 9564.3 | E42: 10131.3 | F42: 10699.2 | G42: 11265.3 | H42: 11832.3 | I42: 12400.2 | J42: 12967.2 | K42: 13534.2 | L42: 14102.1 | M42: 14669.1 | N42: 15235.2 | O42: 15962.4
C43: Note: shaded section indicates 2 motor control boxes required
A45: Structural Extras | H45: Motorisation & Electronics (each Roof requires a Control System + Remote)
A46: 250x50 Beam | F46: 90 | G46: /m | H46: Control System (Includes Motor, 5m Cable, Control Box, Transformer) | N46: 760 | O46: each
A47: 250x50 Beam Corner Joint | F47: 50 | G47: each | H47: Motor Cable - 10m | N47: 100 | O47: each
A48: 250x50 Internal U-Bracket | F48: 30 | G48: each | H48: Rain Sensor | N48: 275 | O48: each
A49: 120mm Posts (Max Length 3800mm) | F49: 360 | G49: each | H49: Remotes & Transmitters
A50: 150mm Posts (Max Length 5400mm) | F50: 360 | G50: each | H50: 3 Button Transmitter - 6 Channel | N50: 95 | O50: each
A51: Post External Base Plate | F51: 60 | G51: each | H51: Lumex Wifi Hub (Multiple Smartphones) | N51: 650 | O51: each
A52: Post Internal U-Bracket | F52: 30 | G52: each | H52: Lumex Bluetooth Hub (1 Smartphone Only) | N52: 355 | O52: each
A53: Roof Mount Bracket | F53: 90 | G53: each | H53: Wifi Interface for Home Automation | N53: 650 | O53: each
A54: Custom Colour Surcharge | F54: 10% - Min $500 | G54: /colour | H54: RS232 Interface for Home Automation | N54: 536 | O54: each
A55: Marine Grade Powdercoat Surcharge | F55: 25% - Min $1300 | G55: /colour | H55: 433MHz Interface for Somfy Control | N55: 250 | O55: each
A56: Woodgrain Powdercoat Surcharge | F56: 25% - Min $1300 | G56: /colour
A57: Drawing Fee (credited once order is in production) | F57: 300 | G57: /order
A58: Raked/Angled Roof | F58: 0.05 | G58: surcharge
A59: When direct wall mounting 250x50 surrounds are not required although recommended for ease of installation.
A60: Lighting
A61: White Light Drivers | E61: Multicoloured Light Drivers | H61: White Lighting | L61: Multicoloured Lighting
A62: Max Power Draw | B62: No. Of Outputs | D62: Price | E62: Max Power Draw | F62: No. Of Outputs | G62: Price | H62: Type | I62: Length | J62: Power Draw | K62: Price | L62: Type | M62: Length | N62: Power Draw | O62: Price
A63: 60w | B63: 1 | D63: $275 each | E63: 150w | F63: 4 | G63: $540 each | H63: Down Light | I63: 1.5m cable | J63: 4.5w/ea | K63: $85 each | L63: Adhesive Strip Light | M63: 5m | N63: 7.5w/m | O63: $330 each
A64: 100w | B64: 1 | D64: $275 each | E64: 185w | F64: 4 | G64: $560 each | H64: Adhesive Strip Light | I64: 5m | J64: 8w/m | K64: $205 each | M64: 7m | N64: 7.5w/m | O64: $470 each
...

Sheet Manual Roof
B2: Roofing | F2: As of | G2: =Cover!I59 -> 46113
A3: Lumex Collection - AltrisShield 140 | E3: Luxe Blinds Shutters Awnings
E4: =IFERROR(IF(-J4/100>0,-J4/100,""),"") -> 0.2 | F4: =IF(E4="","","Discount already applied to the prices below") -> Discount already applied to the prices below | J4: -20
A5: 140mm Louvre Roof Pricing
A6: Pricing includes: Louvres, Beams, Gutters, Gearbox, Crank Handle Note: Roofs over 4000x4000 will be supplied with 2 Gearboxes & Handles
A7: Item Code | C7: Description | E7: Projection (No. of Blades) | F7: Width (Span) | G7: Price Ex. GST | J7: Base Prices
A8: LR140M-6040-W | C8: Louvre Roof 140 Manual Crank: 6000 x 4000 - White | E8: 5845 | F8: 3895 | G8: =J8*(1+$J$4/100) -> 6928 | J8: 8660
A9: LR140M-6040-M | C9: Louvre Roof 140 Manual Crank: 6000 x 4000 - Monument | E9: 5845 | F9: 3895 | G9: =J9*(1+$J$4/100) -> 6928 | J9: 8660
A10: LR140M-5040-W | C10: Louvre Roof 140 Manual Crank: 5000 x 4000 - White | E10: 4935 | F10: 3895 | G10: =J10*(1+$J$4/100) -> 6014.4 | J10: 7518
A11: LR140M-5040-M | C11: Louvre Roof 140 Manual Crank: 5000 x 4000 - Monument | E11: 4935 | F11: 3895 | G11: =J11*(1+$J$4/100) -> 6014.4 | J11: 7518
A12: LR140M-5030-W | C12: Louvre Roof 140 Manual Crank: 5000 x 3000 - White | E12: 4935 | F12: 2985 | G12: =J12*(1+$J$4/100) -> 5087.2 | J12: 6359
A13: LR140M-5030-M | C13: Louvre Roof 140 Manual Crank: 5000 x 3000 - Monument | E13: 4935 | F13: 2985 | G13: =J13*(1+$J$4/100) -> 5087.2 | J13: 6359
A14: LR140M-4040-W | C14: Louvre Roof 140 Manual Crank: 4000 x 4000 - White | E14: 3895 | F14: 3895 | G14: =J14*(1+$J$4/100) -> 4762.4 | J14: 5953
A15: LR140M-4040-M | C15: Louvre Roof 140 Manual Crank: 4000 x 4000 - Monument | E15: 3895 | F15: 3895 | G15: =J15*(1+$J$4/100) -> 4762.4 | J15: 5953
A16: LR140M-3030-W | C16: Louvre Roof 140 Manual Crank: 3000 x 3000 - White | E16: 2985 | F16: 2985 | G16: =J16*(1+$J$4/100) -> 3320 | J16: 4150
A17: LR140M-3030-M | C17: Louvre Roof 140 Manual Crank: 3000 x 3000 - Monument | E17: 2985 | F17: 2985 | G17: =J17*(1+$J$4/100) -> 3320 | J17: 4150
A18: Posts & Accessories
A19: Post Pricing includes Baseplates Note: All 6m x 4m, 5m x 4m, & 5m x 3m systems require a centre Support Post when wall mounted or freestanding.
A20: Item Code | B20: Description | G20: Price Ex. GST
A21: LR140-CP-W | B21: Louvre Roof 140: Corner Post- White (includes Baseplate) 120x120 @ 2750mm | G21: 135
A22: LR140-CP-M | B22: Louvre Roof 140: Corner Post- Monument (includes Baseplate) 120x120 @ 2750mm | G22: 135
A23: LR140-SP-W | B23: Louvre Roof 140: Support Post- White (includes Baseplate) 120x120 @ 2750mm | G23: 135
A24: LR140-SP-M | B24: Louvre Roof 140: Support Post- Monument (includes Baseplate) 120x120 @ 2750mm | G24: 135
A26: All prices are subject to 10% GST
A27: Prices subject to change without notice. All prices subject to CW Systems’ General Terms & Conditions.

Sheet Roller Blinds | Atlas
B2: Blinds | W2: As of | X2: =Cover!AA61 -> 0
A3: Roller Blinds - Atlas Collection | W3: Luxe Blinds Shutters Awnings
W4: =IF(AF4="","","Discount already applied to the prices below") -> Discount already applied to the prices below | AE4: Cat 1 Discount | AF4: -25
AE5: Cat 2 Discount | AF5: -25
AE6: Cat 3 Discount | AF6: -25
B7: Fabric Categories - Atlas Collection | P7: Motorisation
B8: Fabric Name | E8: Fabric Type | H8: Category | K8: Max Width
B9: Essence | E9: Blockout | H9: Category 1 | K9: 3210mm | P9: Somfy
B10: Aristocrat | E10: Blockout | H10: Category 2 | K10: 3210mm | P10: Motors
B11: Boulevard | E11: Light Filtering | H11: Category 2 | K11: 3210mm | P11: Power Source | R11: Control | T11: Description | X11: Price | Z11: Price Per
B12: Verve | E12: Blockout | H12: Category 2 | K12: 3210mm | P12: Battery | R12: RTS | T12: Sonesse 30 2/20 | X12: 280 | Z12: Each
B13: Empyrean | E13: Light Filtering | H13: Category 2 | K13: 3210mm | P13: 240V (Hardwired) | R13: RTS | T13: Altus 40 3/30 | X13: 230 | Z13: Each
B14: Kyoto | E14: Light Filtering | H14: Category 2 | K14: 3210mm | P14: 240V (Hardwired) | R14: RTS | T14: Sonesse 40 3/30 | X14: 370 | Z14: Each
B15: Panorama | E15: Screen 5% & 10% | H15: Category 2 | K15: 3210mm | P15: 240V (Hardwired) | R15: WC | T15: LS 40 3/30 | X15: 200 | Z15: Each
B16: Symphony | E16: Screen 5% | H16: Category 2 | K16: 3210mm | P16: Remotes
B17: Sedona | E17: Light Filtering | H17: Category 2 | K17: 3210mm | P17: Type | R17: Description | X17: Price | Z17: Price Per
B18: Tropicana | E18: Light Filtering | H18: Category 2 | K18: 3210mm | P18: Handheld | R18: 1 Channel Situo White | V18: $85 | X18: 85 | Y18: Each | Z18: Each
B19: Urbania | E19: Light Filtering | H19: Category 2 | K19: 3210mm | P19: Handheld | R19: 5 Channel Situo White | V19: $100 | X19: 100 | Y19: Each | Z19: Each
B20: Velvet | E20: Light Filtering | H20: Category 2 | K20: 3210mm | P20: Handheld | R20: 16 Channel Telis White | V20: $260 | X20: 260 | Y20: Each | Z20: Each
B21: Vogue | E21: Light Filtering | H21: Category 2 | K21: 3210mm | P21: Surface Wall Mount | R21: 1 Channel White | V21: $90 | X21: 90 | Y21: Each | Z21: Each
B22: Boulevard | E22: Blockout | H22: Category 3 | K22: 3210mm | P22: Accessories
B23: Chiffon | E23: Blockout | H23: Category 3 | K23: 3210mm | P23: Description | X23: Price | Z23: Price Per
B24: Empyrean | E24: Blockout | H24: Category 3 | K24: 3210mm | P24: Connexoon | X24: 180 | Y24: $180 | Z24: Each
B25: Lisbon | E25: Blockout | H25: Category 3 | K25: 3210mm | P25: Tahoma Switch | V25: $250 | X25: 250 | Y25: Each | Z25: Each
B26: Kyoto | E26: Blockout | H26: Category 3 | K26: 3210mm | P26: Somfy Charger | V26: $25 | X26: 25 | Y26: Each | Z26: Each
B27: Velvet | E27: Blockout | H27: Category 3 | K27: 3210mm
B28: Montecarlo | E28: Blockout | H28: Category 3 | K28: 3210mm | P28: Automate
B29: Santorini | E29: Blockout | H29: Category 3 | K29: 3210mm | P29: Motors
B30: Sedona | E30: Blockout | H30: Category 3 | K30: 3210mm | P30: Power Source | R30: Control | T30: Description | X30: Price | Z30: Price Per
B31: Tropicana | E31: Blockout | H31: Category 3 | K31: 3210mm | P31: Battery | R31: RTS | T31: Zero Li-ion Q 1.1/28 | X31: 200 | Z31: Each
B32: Urbania | E32: Blockout | H32: Category 3 | K32: 3210mm | P32: Battery | R32: RTS | T32: Zero Li-ion Q 2/28 | X32: 240 | Z32: Each
B33: Vogue | E33: Blockout | H33: Category 3 | K33: 3210mm | P33: Battery | R33: Wand | T33: Magnetic Wand Motor | X33: 70 | Z33: Each
P34: 240V (Hardwired) | R34: RTS | T34: E6 6/33 | X34: 170 | Z34: Each
B35: Hardware & Components | P35: 240V (Hardwired) | R35: WC | T35: M6 6/33 | X35: 140 | Z35: Each
B37: Description | J37: Price | L37: Price Per | P37: Remotes
B38: Silent Bottom Rail | J38: =4*1.5 -> 6 | L38: Blind | P38: Type | R38: Description | X38: Price | Z38: Price Per
B39: Stainless steel chain | J39: 8 | L39: Blind | P39: Handheld | R39: 1 Channel White or Black | X39: 65 | Z39: Each
P40: Handheld | R40: 5 Channel White or Black | X40: 70 | Z40: Each
B41: Double Roller Blind - How to Price Correctly | P41: Handheld | R41: 15 Channel White or Black | X41: 80 | Z41: Each
P42: Handheld | R42: 30 Channel White "Push Pro" | X42: 145 | Z42: Each
...

Sheet Roller Blinds | Wattle
B2: Blinds | W2: As of | X2: =Cover!I59 -> 46113
A3: Roller Blinds -Wattle Collection | W3: Luxe Blinds Shutters Awnings
V4: =IF(AC4="","","Discount already applied to the prices below") -> Discount already applied to the prices below | AB4: Cat 1 Discount | AC4: -25
AB5: Cat 2 Discount | AC5: -25
AB6: Cat 3 Discount | AC6: -25
A7: Fabric Categories - Wattle Collection | O7: Motorisation
A8: Fabric Name | D8: Fabric Type | G8: Category | J8: Max Width | O8: Somfy
A9: Murray | D9: Blockout | G9: Category 1 | J9: 3000mm | O9: Motors
A10: Barossa | D10: Screen 5% & 10% | G10: Category 2 | J10: 3000mm | O10: Power Source | Q10: Control | S10: Description | W10: Price | Y10: Price Per
A11: Bilby | D11: Light Filtering | G11: Category 2 | J11: 2910mm | O11: Battery | Q11: RTS | S11: Sonesse 30 2/20 | W11: 280 | Y11: Each
A12: Fraser | D12: Blockout | G12: Category 2 | J12: 3000mm | O12: 240V (Hardwired) | Q12: RTS | S12: Altus 40 3/30 | W12: 230 | Y12: Each
A13: Kakadu | D13: Light Filtering | G13: Category 2 | J13: 3000mm | O13: 240V (Hardwired) | Q13: RTS | S13: Sonesse 40 3/30 | W13: 370 | Y13: Each
A14: Kakadu | D14: Blockout | G14: Category 2 | J14: 3000mm | O14: 240V (Hardwired) | Q14: WC | S14: LS 40 3/30 | W14: 200 | Y14: Each
A15: Kimberley | D15: Light Filtering | G15: Category 2 | J15: 2910mm | O15: 240V (Hardwired) | Q15: WC | S15: Sonesse 40 3/30 | W15: 345 | Y15: Each
A16: Nullarbor | D16: Blockout | G16: Category 2 | J16: 2800mm | O16: Remotes
A17: Tasman | D17: Light Filtering | G17: Category 2 | J17: 2910mm | O17: Type | Q17: Description | W17: Price | Y17: Price Per
A18: Bilby | D18: Blockout | G18: Category 3 | J18: 2910mm | O18: Handheld | Q18: 1 Channel Situo White | W18: 85 | X18: Each | Y18: Each
A19: Kimberley | D19: Blockout | G19: Category 3 | J19: 2910mm | O19: Handheld | Q19: 5 Channel Situo White | U19: $100 | W19: 100 | X19: Each | Y19: Each
O20: Handheld | Q20: 16 Channel Telis White | U20: $260 | W20: 260 | X20: Each | Y20: Each
A21: Hardware & Components | O21: Wall mount | Q21: 1 Channel White | U21: $90 | W21: 90 | X21: Each | Y21: Each
O22: Accessories
A23: General | O23: Description | W23: Price | Y23: Price Per
A24: Description | I24: Price | K24: Price Per | O24: Connexoon | W24: 180 | Y24: Each
A25: Double Brackets | I25: 12 | K25: Each | O25: Tahoma Switch | W25: 250 | Y25: Each
A26: Slimline Double Brackets (no suitable for linked) | I26: 16 | K26: Each | O26: Somfy Charger | U26: $25 | W26: 25 | X26: Each | Y26: Each
A27: Stainless Steel Chain | I27: 10 | K27: Each | O27: Automate
A28: White/Black Metal Chain | I28: 10 | K28: Each | O28: Motors
A29: Extension Bracket | I29: 4.5 | K29: Blind | O29: Power Source | Q29: Control | S29: Description | W29: Price | Y29: Price Per
A30: Spring Assist Booster | I30: 24 | K30: Blind | O30: Battery | Q30: RTS | S30: Zero Li-ion Q 1.1/28 | W30: 200 | Y30: Each
A31: Flat Bottom Rail | I31: 1.5 | K31: Metre | O31: Battery | Q31: RTS | S31: Zero Li-ion Q 2/28 | W31: 240 | Y31: Each
A32: Silent Bottom Rail | I32: 9 | K32: Metre | O32: Battery | Q32: Wand | S32: Magnetic Wand Motor | W32: 70 | Y32: Each
A33: Fabric Wrapped Bottom Rail | I33: 25 | K33: Metre | O33: 240V (Hardwired) | Q33: RTS | S33: E6 6/33 | W33: 170 | Y33: Each
A34: Bracket Cover | I34: 1.5 | K34: Blind | O34: 240V (Hardwired) | Q34: WC | S34: M6 6/33 | W34: 140 | Y34: Each
A35: Acmeda CF90 Cassette Only | I35: Matrix Priced Below | K35: Blind
A36: Acmeda CF90 Cassette Complete | K36: Blind | O36: Remotes
O37: Type | Q37: Description | W37: Price | Y37: Price Per
O38: Handheld | Q38: 1 Channel White or Black | W38: 65 | Y38: Each
O39: Handheld | Q39: 5 Channel White or Black | W39: 70 | Y39: Each
O40: Handheld | Q40: 15 Channel White or Black | W40: 80 | Y40: Each
O41: Handheld | Q41: 30 Channel White "Push Pro" | W41: 145 | Y41: Each
...

Sheet IB - Venetians
C2: Blinds | W2: Luxe Blinds Shutters Awnings
A4: Venetians Collection | W4: =Cover!I59 -> 46113
AD6: -25
B8: Ultraslat
B10: Ultraslat 50mm
C11: 610 | D11: 710 | E11: 810 | F11: 910 | G11: 1010 | H11: 1110 | I11: 1210 | J11: 1310 | K11: 1410 | L11: 1510 | M11: 1610 | N11: 1710 | O11: 1810 | P11: 1910 | Q11: 2010 | R11: 2110 | S11: 2210 | T11: 2310 | U11: 2410 | V11: 2510 | W11: 2610 | X11: 2710 | AD11: 610 | AE11: 710 | AF11: 810 | AG11: 910 | AH11: 1010 | AI11: 1110 | AJ11: 1210 | AK11: 1310 | AL11: 1410 | AM11: 1510 | AN11: 1610 | AO11: 1710 | AP11: 1810 | AQ11: 1910 | AR11: 2010 | AS11: 2110 | AT11: 2210 | AU11: 2310 | AV11: 2410 | AW11: 2510 | AX11: 2610 | AY11: 2710
B12: 600 | C12: =ROUNDUP(IFERROR(AD12*(1+$AD$6/100),AD12),0) -> 57 | D12: =ROUNDUP(IFERROR(AE12*(1+$AD$6/100),AE12),0) -> 65 | E12: =ROUNDUP(IFERROR(AF12*(1+$AD$6/100),AF12),0) -> 71 | F12: =ROUNDUP(IFERROR(AG12*(1+$AD$6/100),AG12),0) -> 77 | G12: =ROUNDUP(IFERROR(AH12*(1+$AD$6/100),AH12),0) -> 85 | H12: =ROUNDUP(IFERROR(AI12*(1+$AD$6/100),AI12),0) -> 90 | I12: =ROUNDUP(IFERROR(AJ12*(1+$AD$6/100),AJ12),0) -> 96 | J12: =ROUNDUP(IFERROR(AK12*(1+$AD$6/100),AK12),0) -> 106 | ... X12: =ROUNDUP(IFERROR(AY12*(1+$AD$6/100),AY12),0) -> 184 | Y12: 600 | AD12: 76 | AE12: 86 | AF12: 94 | AG12: 102 | AH12: 113 | AI12: 120 | AJ12: 128 | AK12: 141 | AL12: 149 | AM12: 157 | AN12: 164 | AO12: 169 | AP12: 179 | AQ12: 187 | AR12: 194 | AS12: 201 | AT12: 209 | AU12: 216 | AV12: 223 | AW12: 231 | AX12: 238 | AY12: 245
B13: 800 | C13: =ROUNDUP(IFERROR(AD13*(1+$AD$6/100),AD13),0) -> 65 | D13: =ROUNDUP(IFERROR(AE13*(1+$AD$6/100),AE13),0) -> 75 | E13: =ROUNDUP(IFERROR(AF13*(1+$AD$6/100),AF13),0) -> 81 | F13: =ROUNDUP(IFERROR(AG13*(1+$AD$6/100),AG13),0) -> 89 | G13: =ROUNDUP(IFERROR(AH13*(1+$AD$6/100),AH13),0) -> 98 | H13: =ROUNDUP(IFERROR(AI13*(1+$AD$6/100),AI13),0) -> 105 | I13: =ROUNDUP(IFERROR(AJ13*(1+$AD$6/100),AJ13),0) -> 112 | J13: =ROUNDUP(IFERROR(AK13*(1+$AD$6/100),AK13),0) -> 117 | ... X13: =ROUNDUP(IFERROR(AY13*(1+$AD$6/100),AY13),0) -> 216 | Y13: 800 | AD13: 86 | AE13: 99 | AF13: 108 | AG13: 118 | AH13: 130 | AI13: 140 | AJ13: 149 | AK13: 155 | AL13: 164 | AM13: 173 | AN13: 182 | AO13: 196 | AP13: 209 | AQ13: 218 | AR13: 226 | AS13: 235 | AT13: 244 | AU13: 253 | AV13: 262 | AW13: 271 | AX13: 280 | AY13: 288
B14: 1000 | C14: =ROUNDUP(IFERROR(AD14*(1+$AD$6/100),AD14),0) -> 73 | D14: =ROUNDUP(IFERROR(AE14*(1+$AD$6/100),AE14),0) -> 84 | E14: =ROUNDUP(IFERROR(AF14*(1+$AD$6/100),AF14),0) -> 92 | F14: =ROUNDUP(IFERROR(AG14*(1+$AD$6/100),AG14),0) -> 100 | G14: =ROUNDUP(IFERROR(AH14*(1+$AD$6/100),AH14),0) -> 105 | H14: =ROUNDUP(IFERROR(AI14*(1+$AD$6/100),AI14),0) -> 113 | I14: =ROUNDUP(IFERROR(AJ14*(1+$AD$6/100),AJ14),0) -> 120 | J14: =ROUNDUP(IFERROR(AK14*(1+$AD$6/100),AK14),0) -> 132 | ... X14: =ROUNDUP(IFERROR(AY14*(1+$AD$6/100),AY14),0) -> 249 | Y14: 1000 | AD14: 97 | AE14: 111 | AF14: 122 | AG14: 133 | AH14: 140 | AI14: 150 | AJ14: 160 | AK14: 176 | AL14: 187 | AM14: 197 | AN14: 207 | AO14: 224 | AP14: 238 | AQ14: 248 | AR14: 259 | AS14: 269 | AT14: 279 | AU14: 290 | AV14: 300 | AW14: 311 | AX14: 321 | AY14: 332
B15: 1200 | C15: =ROUNDUP(IFERROR(AD15*(1+$AD$6/100),AD15),0) -> 81 | D15: =ROUNDUP(IFERROR(AE15*(1+$AD$6/100),AE15),0) -> 93 | E15: =ROUNDUP(IFERROR(AF15*(1+$AD$6/100),AF15),0) -> 102 | F15: =ROUNDUP(IFERROR(AG15*(1+$AD$6/100),AG15),0) -> 106 | G15: =ROUNDUP(IFERROR(AH15*(1+$AD$6/100),AH15),0) -> 117 | H15: =ROUNDUP(IFERROR(AI15*(1+$AD$6/100),AI15),0) -> 126 | I15: =ROUNDUP(IFERROR(AJ15*(1+$AD$6/100),AJ15),0) -> 135 | J15: =ROUNDUP(IFERROR(AK15*(1+$AD$6/100),AK15),0) -> 148 | ... X15: =ROUNDUP(IFERROR(AY15*(1+$AD$6/100),AY15),0) -> 282 | Y15: 1200 | AD15: 107 | AE15: 123 | AF15: 136 | AG15: 141 | AH15: 156 | AI15: 168 | AJ15: 180 | AK15: 197 | AL15: 209 | AM15: 221 | AN15: 233 | AO15: 252 | AP15: 267 | AQ15: 279 | AR15: 291 | AS15: 303 | AT15: 315 | AU15: 327 | AV15: 339 | AW15: 351 | AX15: 363 | AY15: 375
B16: 1400 | C16: =ROUNDUP(IFERROR(AD16*(1+$AD$6/100),AD16),0) -> 89 | D16: =ROUNDUP(IFERROR(AE16*(1+$AD$6/100),AE16),0) -> 102 | E16: =ROUNDUP(IFERROR(AF16*(1+$AD$6/100),AF16),0) -> 107 | F16: =ROUNDUP(IFERROR(AG16*(1+$AD$6/100),AG16),0) -> 117 | G16: =ROUNDUP(IFERROR(AH16*(1+$AD$6/100),AH16),0) -> 130 | H16: =ROUNDUP(IFERROR(AI16*(1+$AD$6/100),AI16),0) -> 140 | I16: =ROUNDUP(IFERROR(AJ16*(1+$AD$6/100),AJ16),0) -> 150 | J16: =ROUNDUP(IFERROR(AK16*(1+$AD$6/100),AK16),0) -> 165 | ... X16: =ROUNDUP(IFERROR(AY16*(1+$AD$6/100),AY16),0) -> 314 | Y16: 1400 | AD16: 118 | AE16: 136 | AF16: 142 | AG16: 156 | AH16: 173 | AI16: 186 | AJ16: 200 | AK16: 219 | AL16: 232 | AM16: 246 | AN16: 259 | AO16: 279 | AP16: 296 | AQ16: 310 | AR16: 323 | AS16: 337 | AT16: 350 | AU16: 364 | AV16: 377 | AW16: 391 | AX16: 404 | AY16: 418
B17: 1600 | C17: =ROUNDUP(IFERROR(AD17*(1+$AD$6/100),AD17),0) -> 97 | D17: =ROUNDUP(IFERROR(AE17*(1+$AD$6/100),AE17),0) -> 105 | E17: =ROUNDUP(IFERROR(AF17*(1+$AD$6/100),AF17),0) -> 117 | F17: =ROUNDUP(IFERROR(AG17*(1+$AD$6/100),AG17),0) -> 128 | G17: =ROUNDUP(IFERROR(AH17*(1+$AD$6/100),AH17),0) -> 142 | H17: =ROUNDUP(IFERROR(AI17*(1+$AD$6/100),AI17),0) -> 153 | I17: =ROUNDUP(IFERROR(AJ17*(1+$AD$6/100),AJ17),0) -> 165 | J17: =ROUNDUP(IFERROR(AK17*(1+$AD$6/100),AK17),0) -> 180 | ... X17: =ROUNDUP(IFERROR(AY17*(1+$AD$6/100),AY17),0) -> 346 | Y17: 1600 | AD17: 129 | AE17: 140 | AF17: 155 | AG17: 170 | AH17: 189 | AI17: 204 | AJ17: 219 | AK17: 240 | AL17: 255 | AM17: 270 | AN17: 285 | AO17: 307 | AP17: 325 | AQ17: 340 | AR17: 355 | AS17: 371 | AT17: 386 | AU17: 401 | AV17: 416 | AW17: 431 | AX17: 446 | AY17: 461
B18: 1800 | C18: =ROUNDUP(IFERROR(AD18*(1+$AD$6/100),AD18),0) -> 101 | D18: =ROUNDUP(IFERROR(AE18*(1+$AD$6/100),AE18),0) -> 116 | E18: =ROUNDUP(IFERROR(AF18*(1+$AD$6/100),AF18),0) -> 129 | F18: =ROUNDUP(IFERROR(AG18*(1+$AD$6/100),AG18),0) -> 141 | G18: =ROUNDUP(IFERROR(AH18*(1+$AD$6/100),AH18),0) -> 156 | H18: =ROUNDUP(IFERROR(AI18*(1+$AD$6/100),AI18),0) -> 168 | I18: =ROUNDUP(IFERROR(AJ18*(1+$AD$6/100),AJ18),0) -> 181 | J18: =ROUNDUP(IFERROR(AK18*(1+$AD$6/100),AK18),0) -> 196 | ... X18: =ROUNDUP(IFERROR(AY18*(1+$AD$6/100),AY18),0) -> 378 | Y18: 1800 | AD18: 134 | AE18: 154 | AF18: 171 | AG18: 187 | AH18: 208 | AI18: 224 | AJ18: 241 | AK18: 261 | AL18: 278 | AM18: 294 | AN18: 311 | AO18: 335 | AP18: 354 | AQ18: 371 | AR18: 388 | AS18: 404 | AT18: 421 | AU18: 438 | AV18: 454 | AW18: 471 | AX18: 488 | AY18: 504
B19: 2000 | C19: =ROUNDUP(IFERROR(AD19*(1+$AD$6/100),AD19),0) -> 108 | D19: =ROUNDUP(IFERROR(AE19*(1+$AD$6/100),AE19),0) -> 125 | E19: =ROUNDUP(IFERROR(AF19*(1+$AD$6/100),AF19),0) -> 138 | F19: =ROUNDUP(IFERROR(AG19*(1+$AD$6/100),AG19),0) -> 152 | G19: =ROUNDUP(IFERROR(AH19*(1+$AD$6/100),AH19),0) -> 168 | H19: =ROUNDUP(IFERROR(AI19*(1+$AD$6/100),AI19),0) -> 182 | I19: =ROUNDUP(IFERROR(AJ19*(1+$AD$6/100),AJ19),0) -> 195 | J19: =ROUNDUP(IFERROR(AK19*(1+$AD$6/100),AK19),0) -> 212 | ... X19: =ROUNDUP(IFERROR(AY19*(1+$AD$6/100),AY19),0) -> 411 | Y19: 2000 | AD19: 144 | AE19: 166 | AF19: 184 | AG19: 202 | AH19: 224 | AI19: 242 | AJ19: 260 | AK19: 282 | AL19: 300 | AM19: 319 | AN19: 337 | AO19: 362 | AP19: 384 | AQ19: 402 | AR19: 420 | AS19: 438 | AT19: 456 | AU19: 475 | AV19: 493 | AW19: 511 | AX19: 529 | AY19: 547
B20: 2200 | C20: =ROUNDUP(IFERROR(AD20*(1+$AD$6/100),AD20),0) -> 116 | D20: =ROUNDUP(IFERROR(AE20*(1+$AD$6/100),AE20),0) -> 133 | E20: =ROUNDUP(IFERROR(AF20*(1+$AD$6/100),AF20),0) -> 148 | F20: =ROUNDUP(IFERROR(AG20*(1+$AD$6/100),AG20),0) -> 163 | G20: =ROUNDUP(IFERROR(AH20*(1+$AD$6/100),AH20),0) -> 180 | H20: =ROUNDUP(IFERROR(AI20*(1+$AD$6/100),AI20),0) -> 195 | I20: =ROUNDUP(IFERROR(AJ20*(1+$AD$6/100),AJ20),0) -> 210 | J20: =ROUNDUP(IFERROR(AK20*(1+$AD$6/100),AK20),0) -> 228 | ... X20: =ROUNDUP(IFERROR(AY20*(1+$AD$6/100),AY20),0) -> 444 | Y20: 2200 | AD20: 154 | AE20: 177 | AF20: 197 | AG20: 217 | AH20: 240 | AI20: 260 | AJ20: 280 | AK20: 303 | AL20: 323 | AM20: 343 | AN20: 363 | AO20: 390 | AP20: 413 | AQ20: 433 | AR20: 452 | AS20: 472 | AT20: 492 | AU20: 512 | AV20: 531 | AW20: 551 | AX20: 571 | AY20: 591
B21: 2400 | C21: =ROUNDUP(IFERROR(AD21*(1+$AD$6/100),AD21),0) -> 126 | D21: =ROUNDUP(IFERROR(AE21*(1+$AD$6/100),AE21),0) -> 144 | E21: =ROUNDUP(IFERROR(AF21*(1+$AD$6/100),AF21),0) -> 161 | F21: =ROUNDUP(IFERROR(AG21*(1+$AD$6/100),AG21),0) -> 177 | G21: =ROUNDUP(IFERROR(AH21*(1+$AD$6/100),AH21),0) -> 195 | H21: =ROUNDUP(IFERROR(AI21*(1+$AD$6/100),AI21),0) -> 211 | I21: =ROUNDUP(IFERROR(AJ21*(1+$AD$6/100),AJ21),0) -> 228 | J21: =ROUNDUP(IFERROR(AK21*(1+$AD$6/100),AK21),0) -> 246 | ... U21: =ROUNDUP(IFERROR(AV21*(1+$AD$6/100),AV21),0) -> 428 | V21: N/A | W21: N/A | X21: N/A | Y21: 2400 | AD21: 167 | AE21: 192 | AF21: 214 | AG21: 235 | AH21: 260 | AI21: 281 | AJ21: 303 | AK21: 328 | AL21: 349 | AM21: 370 | AN21: 392 | AO21: 421 | AP21: 442 | AQ21: 463 | AR21: 485 | AS21: 506 | AT21: 527 | AU21: 549 | AV21: 570 | AW21: 0 | AX21: 0 | AY21: 0
B22: 2600 | C22: =ROUNDUP(IFERROR(AD22*(1+$AD$6/100),AD22),0) -> 133 | D22: =ROUNDUP(IFERROR(AE22*(1+$AD$6/100),AE22),0) -> 153 | E22: =ROUNDUP(IFERROR(AF22*(1+$AD$6/100),AF22),0) -> 171 | F22: =ROUNDUP(IFERROR(AG22*(1+$AD$6/100),AG22),0) -> 188 | G22: =ROUNDUP(IFERROR(AH22*(1+$AD$6/100),AH22),0) -> 207 | H22: =ROUNDUP(IFERROR(AI22*(1+$AD$6/100),AI22),0) -> 225 | I22: =ROUNDUP(IFERROR(AJ22*(1+$AD$6/100),AJ22),0) -> 242 | J22: =ROUNDUP(IFERROR(AK22*(1+$AD$6/100),AK22),0) -> 262 | ... S22: =ROUNDUP(IFERROR(AT22*(1+$AD$6/100),AT22),0) -> 423 | T22: N/A | U22: N/A | V22: N/A | W22: N/A | X22: N/A | Y22: 2600 | AD22: 177 | AE22: 204 | AF22: 227 | AG22: 250 | AH22: 276 | AI22: 299 | AJ22: 322 | AK22: 349 | AL22: 372 | AM22: 395 | AN22: 418 | AO22: 448 | AP22: 471 | AQ22: 494 | AR22: 517 | AS22: 540 | AT22: 563 | AU22: 0 | AV22: 0 | AW22: 0 | AX22: 0 | AY22: 0
B23: 2800 | C23: =ROUNDUP(IFERROR(AD23*(1+$AD$6/100),AD23),0) -> 141 | D23: =ROUNDUP(IFERROR(AE23*(1+$AD$6/100),AE23),0) -> 162 | E23: =ROUNDUP(IFERROR(AF23*(1+$AD$6/100),AF23),0) -> 180 | F23: =ROUNDUP(IFERROR(AG23*(1+$AD$6/100),AG23),0) -> 198 | G23: =ROUNDUP(IFERROR(AH23*(1+$AD$6/100),AH23),0) -> 220 | H23: =ROUNDUP(IFERROR(AI23*(1+$AD$6/100),AI23),0) -> 238 | I23: =ROUNDUP(IFERROR(AJ23*(1+$AD$6/100),AJ23),0) -> 257 | J23: =ROUNDUP(IFERROR(AK23*(1+$AD$6/100),AK23),0) -> 278 | ... R23: =ROUNDUP(IFERROR(AS23*(1+$AD$6/100),AS23),0) -> 431 | S23: N/A | T23: N/A | U23: N/A | V23: N/A | W23: N/A | X23: N/A | Y23: 2800 | AD23: 187 | AE23: 216 | AF23: 240 | AG23: 264 | AH23: 293 | AI23: 317 | AJ23: 342 | AK23: 370 | AL23: 395 | AM23: 419 | AN23: 444 | AO23: 476 | AP23: 500 | AQ23: 525 | AR23: 549 | AS23: 574 | AT23: 0 | AU23: 0 | AV23: 0 | AW23: 0 | AX23: 0 | AY23: 0
B24: 3000 | C24: =ROUNDUP(IFERROR(AD24*(1+$AD$6/100),AD24),0) -> 148 | D24: =ROUNDUP(IFERROR(AE24*(1+$AD$6/100),AE24),0) -> 171 | E24: =ROUNDUP(IFERROR(AF24*(1+$AD$6/100),AF24),0) -> 190 | F24: =ROUNDUP(IFERROR(AG24*(1+$AD$6/100),AG24),0) -> 210 | G24: =ROUNDUP(IFERROR(AH24*(1+$AD$6/100),AH24),0) -> 232 | H24: =ROUNDUP(IFERROR(AI24*(1+$AD$6/100),AI24),0) -> 252 | I24: =ROUNDUP(IFERROR(AJ24*(1+$AD$6/100),AJ24),0) -> 271 | J24: =ROUNDUP(IFERROR(AK24*(1+$AD$6/100),AK24),0) -> 294 | ... P24: =ROUNDUP(IFERROR(AQ24*(1+$AD$6/100),AQ24),0) -> 417 | Q24: N/A | R24: N/A | S24: N/A | T24: N/A | U24: N/A | V24: N/A | W24: N/A | X24: N/A | Y24: 3000 | AD24: 197 | AE24: 227 | AF24: 253 | AG24: 279 | AH24: 309 | AI24: 335 | AJ24: 361 | AK24: 391 | AL24: 417 | AM24: 443 | AN24: 469 | AO24: 503 | AP24: 529 | AQ24: 555 | AR24: 0 | AS24: 0 | AT24: 0 | AU24: 0 | AV24: 0 | AW24: 0 | AX24: 0 | AY24: 0
B25: 3200 | C25: =ROUNDUP(IFERROR(AD25*(1+$AD$6/100),AD25),0) -> 156 | D25: =ROUNDUP(IFERROR(AE25*(1+$AD$6/100),AE25),0) -> 180 | E25: =ROUNDUP(IFERROR(AF25*(1+$AD$6/100),AF25),0) -> 200 | F25: =ROUNDUP(IFERROR(AG25*(1+$AD$6/100),AG25),0) -> 221 | G25: =ROUNDUP(IFERROR(AH25*(1+$AD$6/100),AH25),0) -> 245 | H25: =ROUNDUP(IFERROR(AI25*(1+$AD$6/100),AI25),0) -> 265 | I25: =ROUNDUP(IFERROR(AJ25*(1+$AD$6/100),AJ25),0) -> 286 | J25: =ROUNDUP(IFERROR(AK25*(1+$AD$6/100),AK25),0) -> 310 | ... O25: =ROUNDUP(IFERROR(AP25*(1+$AD$6/100),AP25),0) -> 420 | P25: N/A | Q25: N/A | R25: N/A | S25: N/A | T25: N/A | U25: N/A | V25: N/A | W25: N/A | X25: N/A | Y25: 3200 | AD25: 207 | AE25: 239 | AF25: 266 | AG25: 294 | AH25: 326 | AI25: 353 | AJ25: 381 | AK25: 413 | AL25: 440 | AM25: 468 | AN25: 495 | AO25: 531 | AP25: 559 | AQ25: 0 | AR25: 0 | AS25: 0 | AT25: 0 | AU25: 0 | AV25: 0 | AW25: 0 | AX25: 0 | AY25: 0
AD27: 0 | AE27: 0 | AF27: 0 | AG27: 0 | AH27: 0 | AI27: 0 | AJ27: 0 | AK27: 0 | AL27: 0 | AM27: 0 | AN27: 0 | AO27: 0 | AP27: 0 | AQ27: 0 | AR27: 0 | AS27: 0 | AT27: 0 | AU27: 0 | AV27: 0 | AW27: 0 | AX27: 0 | AY27: 0
B28: Ultraslat 63mm | AD28: 0 | AE28: 0 | AF28: 0 | AG28: 0 | AH28: 0 | AI28: 0 | AJ28: 0 | AK28: 0 | AL28: 0 | AM28: 0 | AN28: 0 | AO28: 0 | AP28: 0 | AQ28: 0 | AR28: 0 | AS28: 0 | AT28: 0 | AU28: 0 | AV28: 0 | AW28: 0 | AX28: 0 | AY28: 0
C29: 610 | D29: 710 | E29: 810 | F29: 910 | G29: 1010 | H29: 1110 | I29: 1210 | J29: 1310 | K29: 1410 | L29: 1510 | M29: 1610 | N29: 1710 | O29: 1810 | P29: 1910 | Q29: 2010 | R29: 2110 | S29: 2210 | T29: 2310 | U29: 2410 | V29: 2510 | W29: 2610 | X29: 2710 | AD29: 610 | AE29: 710 | AF29: 810 | AG29: 910 | AH29: 1010 | AI29: 1110 | AJ29: 1210 | AK29: 1310 | AL29: 1410 | AM29: 1510 | AN29: 1610 | AO29: 1710 | AP29: 1810 | AQ29: 1910 | AR29: 2010 | AS29: 2110 | AT29: 2210 | AU29: 2310 | AV29: 2410 | AW29: 2510 | AX29: 2610 | AY29: 2710
B30: 600 | C30: =ROUNDUP(IFERROR(AD30*(1+$AD$6/100),AD30),0) -> 68 | D30: =ROUNDUP(IFERROR(AE30*(1+$AD$6/100),AE30),0) -> 78 | E30: =ROUNDUP(IFERROR(AF30*(1+$AD$6/100),AF30),0) -> 84 | F30: =ROUNDUP(IFERROR(AG30*(1+$AD$6/100),AG30),0) -> 92 | G30: =ROUNDUP(IFERROR(AH30*(1+$AD$6/100),AH30),0) -> 102 | H30: =ROUNDUP(IFERROR(AI30*(1+$AD$6/100),AI30),0) -> 108 | I30: =ROUNDUP(IFERROR(AJ30*(1+$AD$6/100),AJ30),0) -> 115 | J30: =ROUNDUP(IFERROR(AK30*(1+$AD$6/100),AK30),0) -> 127 | ... X30: =ROUNDUP(IFERROR(AY30*(1+$AD$6/100),AY30),0) -> 220 | AD30: 90 | AE30: 103 | AF30: 112 | AG30: 122 | AH30: 135 | AI30: 144 | AJ30: 153 | AK30: 169 | AL30: 178 | AM30: 187 | AN30: 197 | AO30: 202 | AP30: 214 | AQ30: 223 | AR30: 232 | AS30: 241 | AT30: 249 | AU30: 258 | AV30: 267 | AW30: 276 | AX30: 284 | AY30: 293
B31: 800 | C31: =ROUNDUP(IFERROR(AD31*(1+$AD$6/100),AD31),0) -> 78 | D31: =ROUNDUP(IFERROR(AE31*(1+$AD$6/100),AE31),0) -> 89 | E31: =ROUNDUP(IFERROR(AF31*(1+$AD$6/100),AF31),0) -> 97 | F31: =ROUNDUP(IFERROR(AG31*(1+$AD$6/100),AG31),0) -> 105 | G31: =ROUNDUP(IFERROR(AH31*(1+$AD$6/100),AH31),0) -> 117 | H31: =ROUNDUP(IFERROR(AI31*(1+$AD$6/100),AI31),0) -> 126 | I31: =ROUNDUP(IFERROR(AJ31*(1+$AD$6/100),AJ31),0) -> 134 | J31: =ROUNDUP(IFERROR(AK31*(1+$AD$6/100),AK31),0) -> 139 | ... X31: =ROUNDUP(IFERROR(AY31*(1+$AD$6/100),AY31),0) -> 259 | AD31: 103 | AE31: 118 | AF31: 129 | AG31: 140 | AH31: 156 | AI31: 167 | AJ31: 178 | AK31: 185 | AL31: 196 | AM31: 206 | AN31: 217 | AO31: 235 | AP31: 249 | AQ31: 260 | AR31: 271 | AS31: 281 | AT31: 292 | AU31: 302 | AV31: 313 | AW31: 324 | AX31: 334 | AY31: 345
B32: 1000 | C32: =ROUNDUP(IFERROR(AD32*(1+$AD$6/100),AD32),0) -> 87 | D32: =ROUNDUP(IFERROR(AE32*(1+$AD$6/100),AE32),0) -> 100 | E32: =ROUNDUP(IFERROR(AF32*(1+$AD$6/100),AF32),0) -> 110 | F32: =ROUNDUP(IFERROR(AG32*(1+$AD$6/100),AG32),0) -> 120 | G32: =ROUNDUP(IFERROR(AH32*(1+$AD$6/100),AH32),0) -> 126 | H32: =ROUNDUP(IFERROR(AI32*(1+$AD$6/100),AI32),0) -> 135 | I32: =ROUNDUP(IFERROR(AJ32*(1+$AD$6/100),AJ32),0) -> 144 | J32: =ROUNDUP(IFERROR(AK32*(1+$AD$6/100),AK32),0) -> 159 | ... X32: =ROUNDUP(IFERROR(AY32*(1+$AD$6/100),AY32),0) -> 297 | AD32: 116 | AE32: 133 | AF32: 146 | AG32: 159 | AH32: 167 | AI32: 179 | AJ32: 192 | AK32: 211 | AL32: 223 | AM32: 236 | AN32: 248 | AO32: 268 | AP32: 284 | AQ32: 297 | AR32: 309 | AS32: 322 | AT32: 334 | AU32: 347 | AV32: 359 | AW32: 371 | AX32: 384 | AY32: 396
B33: 1200 | C33: =ROUNDUP(IFERROR(AD33*(1+$AD$6/100),AD33),0) -> 96 | D33: =ROUNDUP(IFERROR(AE33*(1+$AD$6/100),AE33),0) -> 111 | E33: =ROUNDUP(IFERROR(AF33*(1+$AD$6/100),AF33),0) -> 123 | F33: =ROUNDUP(IFERROR(AG33*(1+$AD$6/100),AG33),0) -> 126 | G33: =ROUNDUP(IFERROR(AH33*(1+$AD$6/100),AH33),0) -> 141 | H33: =ROUNDUP(IFERROR(AI33*(1+$AD$6/100),AI33),0) -> 151 | I33: =ROUNDUP(IFERROR(AJ33*(1+$AD$6/100),AJ33),0) -> 162 | J33: =ROUNDUP(IFERROR(AK33*(1+$AD$6/100),AK33),0) -> 177 | ... X33: =ROUNDUP(IFERROR(AY33*(1+$AD$6/100),AY33),0) -> 336 | AD33: 128 | AE33: 148 | AF33: 163 | AG33: 168 | AH33: 187 | AI33: 201 | AJ33: 215 | AK33: 236 | AL33: 250 | AM33: 265 | AN33: 279 | AO33: 301 | AP33: 319 | AQ33: 333 | AR33: 348 | AS33: 362 | AT33: 376 | AU33: 391 | AV33: 405 | AW33: 419 | AX33: 434 | AY33: 448
B34: 1400 | C34: =ROUNDUP(IFERROR(AD34*(1+$AD$6/100),AD34),0) -> 106 | D34: =ROUNDUP(IFERROR(AE34*(1+$AD$6/100),AE34),0) -> 122 | E34: =ROUNDUP(IFERROR(AF34*(1+$AD$6/100),AF34),0) -> 128 | F34: =ROUNDUP(IFERROR(AG34*(1+$AD$6/100),AG34),0) -> 140 | G34: =ROUNDUP(IFERROR(AH34*(1+$AD$6/100),AH34),0) -> 155 | H34: =ROUNDUP(IFERROR(AI34*(1+$AD$6/100),AI34),0) -> 167 | I34: =ROUNDUP(IFERROR(AJ34*(1+$AD$6/100),AJ34),0) -> 180 | J34: =ROUNDUP(IFERROR(AK34*(1+$AD$6/100),AK34),0) -> 196 | ... X34: =ROUNDUP(IFERROR(AY34*(1+$AD$6/100),AY34),0) -> 375 | AD34: 141 | AE34: 162 | AF34: 170 | AG34: 186 | AH34: 206 | AI34: 222 | AJ34: 239 | AK34: 261 | AL34: 277 | AM34: 294 | AN34: 310 | AO34: 334 | AP34: 354 | AQ34: 370 | AR34: 386 | AS34: 403 | AT34: 419 | AU34: 435 | AV34: 451 | AW34: 467 | AX34: 483 | AY34: 500
B35: 1600 | C35: =ROUNDUP(IFERROR(AD35*(1+$AD$6/100),AD35),0) -> 116 | D35: =ROUNDUP(IFERROR(AE35*(1+$AD$6/100),AE35),0) -> 126 | E35: =ROUNDUP(IFERROR(AF35*(1+$AD$6/100),AF35),0) -> 140 | F35: =ROUNDUP(IFERROR(AG35*(1+$AD$6/100),AG35),0) -> 153 | G35: =ROUNDUP(IFERROR(AH35*(1+$AD$6/100),AH35),0) -> 170 | H35: =ROUNDUP(IFERROR(AI35*(1+$AD$6/100),AI35),0) -> 183 | I35: =ROUNDUP(IFERROR(AJ35*(1+$AD$6/100),AJ35),0) -> 197 | J35: =ROUNDUP(IFERROR(AK35*(1+$AD$6/100),AK35),0) -> 216 | ... X35: =ROUNDUP(IFERROR(AY35*(1+$AD$6/100),AY35),0) -> 414 | AD35: 154 | AE35: 168 | AF35: 186 | AG35: 204 | AH35: 226 | AI35: 244 | AJ35: 262 | AK35: 287 | AL35: 305 | AM35: 323 | AN35: 341 | AO35: 367 | AP35: 389 | AQ35: 407 | AR35: 425 | AS35: 443 | AT35: 461 | AU35: 479 | AV35: 497 | AW35: 515 | AX35: 533 | AY35: 551
B36: 1800 | C36: =ROUNDUP(IFERROR(AD36*(1+$AD$6/100),AD36),0) -> 120 | D36: =ROUNDUP(IFERROR(AE36*(1+$AD$6/100),AE36),0) -> 138 | E36: =ROUNDUP(IFERROR(AF36*(1+$AD$6/100),AF36),0) -> 153 | F36: =ROUNDUP(IFERROR(AG36*(1+$AD$6/100),AG36),0) -> 168 | G36: =ROUNDUP(IFERROR(AH36*(1+$AD$6/100),AH36),0) -> 186 | H36: =ROUNDUP(IFERROR(AI36*(1+$AD$6/100),AI36),0) -> 201 | I36: =ROUNDUP(IFERROR(AJ36*(1+$AD$6/100),AJ36),0) -> 216 | J36: =ROUNDUP(IFERROR(AK36*(1+$AD$6/100),AK36),0) -> 234 | ... X36: =ROUNDUP(IFERROR(AY36*(1+$AD$6/100),AY36),0) -> 453 | AD36: 160 | AE36: 184 | AF36: 204 | AG36: 224 | AH36: 248 | AI36: 268 | AJ36: 288 | AK36: 312 | AL36: 332 | AM36: 352 | AN36: 372 | AO36: 400 | AP36: 424 | AQ36: 444 | AR36: 464 | AS36: 483 | AT36: 503 | AU36: 523 | AV36: 543 | AW36: 563 | AX36: 583 | AY36: 603
B37: 2000 | C37: =ROUNDUP(IFERROR(AD37*(1+$AD$6/100),AD37),0) -> 129 | D37: =ROUNDUP(IFERROR(AE37*(1+$AD$6/100),AE37),0) -> 149 | E37: =ROUNDUP(IFERROR(AF37*(1+$AD$6/100),AF37),0) -> 165 | F37: =ROUNDUP(IFERROR(AG37*(1+$AD$6/100),AG37),0) -> 182 | G37: =ROUNDUP(IFERROR(AH37*(1+$AD$6/100),AH37),0) -> 201 | H37: =ROUNDUP(IFERROR(AI37*(1+$AD$6/100),AI37),0) -> 217 | I37: =ROUNDUP(IFERROR(AJ37*(1+$AD$6/100),AJ37),0) -> 234 | J37: =ROUNDUP(IFERROR(AK37*(1+$AD$6/100),AK37),0) -> 253 | ... X37: =ROUNDUP(IFERROR(AY37*(1+$AD$6/100),AY37),0) -> 491 | AD37: 172 | AE37: 198 | AF37: 220 | AG37: 242 | AH37: 268 | AI37: 289 | AJ37: 311 | AK37: 337 | AL37: 359 | AM37: 381 | AN37: 403 | AO37: 433 | AP37: 459 | AQ37: 480 | AR37: 502 | AS37: 524 | AT37: 546 | AU37: 567 | AV37: 589 | AW37: 611 | AX37: 633 | AY37: 654
B38: 2200 | C38: =ROUNDUP(IFERROR(AD38*(1+$AD$6/100),AD38),0) -> 138 | D38: =ROUNDUP(IFERROR(AE38*(1+$AD$6/100),AE38),0) -> 159 | E38: =ROUNDUP(IFERROR(AF38*(1+$AD$6/100),AF38),0) -> 177 | F38: =ROUNDUP(IFERROR(AG38*(1+$AD$6/100),AG38),0) -> 195 | G38: =ROUNDUP(IFERROR(AH38*(1+$AD$6/100),AH38),0) -> 216 | H38: =ROUNDUP(IFERROR(AI38*(1+$AD$6/100),AI38),0) -> 234 | I38: =ROUNDUP(IFERROR(AJ38*(1+$AD$6/100),AJ38),0) -> 252 | J38: =ROUNDUP(IFERROR(AK38*(1+$AD$6/100),AK38),0) -> 273 | ... X38: =ROUNDUP(IFERROR(AY38*(1+$AD$6/100),AY38),0) -> 530 | AD38: 184 | AE38: 212 | AF38: 236 | AG38: 259 | AH38: 287 | AI38: 311 | AJ38: 335 | AK38: 363 | AL38: 386 | AM38: 410 | AN38: 434 | AO38: 466 | AP38: 493 | AQ38: 517 | AR38: 541 | AS38: 564 | AT38: 588 | AU38: 612 | AV38: 635 | AW38: 659 | AX38: 683 | AY38: 706
B39: 2400 | C39: =ROUNDUP(IFERROR(AD39*(1+$AD$6/100),AD39),0) -> 150 | D39: =ROUNDUP(IFERROR(AE39*(1+$AD$6/100),AE39),0) -> 173 | E39: =ROUNDUP(IFERROR(AF39*(1+$AD$6/100),AF39),0) -> 192 | F39: =ROUNDUP(IFERROR(AG39*(1+$AD$6/100),AG39),0) -> 211 | G39: =ROUNDUP(IFERROR(AH39*(1+$AD$6/100),AH39),0) -> 234 | H39: =ROUNDUP(IFERROR(AI39*(1+$AD$6/100),AI39),0) -> 252 | I39: =ROUNDUP(IFERROR(AJ39*(1+$AD$6/100),AJ39),0) -> 272 | J39: =ROUNDUP(IFERROR(AK39*(1+$AD$6/100),AK39),0) -> 294 | ... U39: =ROUNDUP(IFERROR(AV39*(1+$AD$6/100),AV39),0) -> 511 | V39: N/A | W39: N/A | X39: N/A | AD39: 200 | AE39: 230 | AF39: 255 | AG39: 281 | AH39: 311 | AI39: 336 | AJ39: 362 | AK39: 392 | AL39: 417 | AM39: 443 | AN39: 468 | AO39: 503 | AP39: 528 | AQ39: 554 | AR39: 579 | AS39: 605 | AT39: 630 | AU39: 656 | AV39: 681 | AW39: 0 | AX39: 0 | AY39: 0
B40: 2600 | C40: =ROUNDUP(IFERROR(AD40*(1+$AD$6/100),AD40),0) -> 159 | D40: =ROUNDUP(IFERROR(AE40*(1+$AD$6/100),AE40),0) -> 183 | E40: =ROUNDUP(IFERROR(AF40*(1+$AD$6/100),AF40),0) -> 204 | F40: =ROUNDUP(IFERROR(AG40*(1+$AD$6/100),AG40),0) -> 224 | G40: =ROUNDUP(IFERROR(AH40*(1+$AD$6/100),AH40),0) -> 248 | H40: =ROUNDUP(IFERROR(AI40*(1+$AD$6/100),AI40),0) -> 269 | I40: =ROUNDUP(IFERROR(AJ40*(1+$AD$6/100),AJ40),0) -> 289 | J40: =ROUNDUP(IFERROR(AK40*(1+$AD$6/100),AK40),0) -> 313 | ... S40: =ROUNDUP(IFERROR(AT40*(1+$AD$6/100),AT40),0) -> 505 | T40: N/A | U40: N/A | V40: N/A | W40: N/A | X40: N/A | AD40: 212 | AE40: 244 | AF40: 271 | AG40: 298 | AH40: 330 | AI40: 358 | AJ40: 385 | AK40: 417 | AL40: 445 | AM40: 472 | AN40: 499 | AO40: 536 | AP40: 563 | AQ40: 591 | AR40: 618 | AS40: 645 | AT40: 673 | AU40: 0 | AV40: 0 | AW40: 0 | AX40: 0 | AY40: 0
B41: 2800 | C41: =ROUNDUP(IFERROR(AD41*(1+$AD$6/100),AD41),0) -> 168 | D41: =ROUNDUP(IFERROR(AE41*(1+$AD$6/100),AE41),0) -> 194 | E41: =ROUNDUP(IFERROR(AF41*(1+$AD$6/100),AF41),0) -> 216 | F41: =ROUNDUP(IFERROR(AG41*(1+$AD$6/100),AG41),0) -> 237 | G41: =ROUNDUP(IFERROR(AH41*(1+$AD$6/100),AH41),0) -> 263 | H41: =ROUNDUP(IFERROR(AI41*(1+$AD$6/100),AI41),0) -> 285 | I41: =ROUNDUP(IFERROR(AJ41*(1+$AD$6/100),AJ41),0) -> 307 | J41: =ROUNDUP(IFERROR(AK41*(1+$AD$6/100),AK41),0) -> 332 | ... R41: =ROUNDUP(IFERROR(AS41*(1+$AD$6/100),AS41),0) -> 515 | S41: N/A | T41: N/A | U41: N/A | V41: N/A | W41: N/A | X41: N/A | AD41: 224 | AE41: 258 | AF41: 287 | AG41: 316 | AH41: 350 | AI41: 379 | AJ41: 409 | AK41: 442 | AL41: 472 | AM41: 501 | AN41: 530 | AO41: 569 | AP41: 598 | AQ41: 627 | AR41: 657 | AS41: 686 | AT41: 0 | AU41: 0 | AV41: 0 | AW41: 0 | AX41: 0 | AY41: 0
